Workbook

Sheet P1
A1: Enclosure IV
A2: SWD Form J2 (LSG)
A3: (Revised April 2002)
A4: DSWO: Wong Tai Sin (District)
A5: Integrated Team of Young People Services
A6: (for Lumps Sum Grant agencies)
A7: (to be submitted in triplicate to Service Performance Section
A8: Collectively through head office of respective agency
A9: With a copy to concerned DSWO
A10: on or before 20th of April, July, October and January)
A12: Name of Team : Children & Youth Integrated Services________________
A13: Name of Agency : __The Community Service Association_
... A21: (Agreed Level: 1400 in the year ending 31 March)
B23: Children Member | E23: Youth Member | K23: Parent Member | N23: Total No.
B24: (14 or Below) | E24: Aged 15 to 24 | H24: Aged 25 or Above | N24: of Member
A25: Month | E25: =B25 -> 0 | F25: =C25 -> 0 | G25: =D25 -> 0 | H25: =B25 -> 0 | I25: =C25 -> 0 | J25: =D25 -> 0 | K25: =B25 -> 0 | L25: =C25 -> 0 | M25: =D25 -> 0 | N25: =B25 -> 0 | O25: =C25 -> 0 | P25: =D25 -> 0
A26: Members
A27: i.Total no. of new and renewed members b/f from past period | C27: =B31 -> 0 | D27: =C31 -> 0 | F27: =E31 -> 0 | G27: =F31 -> 0 | I27: =H31 -> 0 | J27: =I31 -> 0 | L27: =K31 -> 0 | M27: =L31 -> 0 | N27: =B27+E27+H27+K27 -> 0 | O27: =C27+F27+I27+L27 -> 0 | P27: =D27+G27+J27+M27 -> 0
A29: ii. No. of new members and renewed members | N29: =B29+E29+H29+K29 -> 0 | O29: =C29+F29+I29+L29 -> 0 | P29: =D29+G29+J29+M29 -> 0
A31: iii.Total no. of new and renewed members at the end of period (Output Standard 1) (i.e.i + ii ) | B31: =B27+B29 -> 0 | C31: =C27+C29 -> 0 | D31: =D27+D29 -> 0 | E31: =E27+E29 -> 0 | F31: =F27+F29 -> 0 | G31: =G27+G29 -> 0 | H31: =H27+H29 -> 0 | I31: =I27+I29 -> 0 | ... M31: =M27+M29 -> 0 | N31: =B31+E31+H31+K31 -> 0 | O31: =C31+F31+I31+L31 -> 0 | P31: =D31+G31+J31+M31 -> 0 | Q31: =Q27+Q29 -> 0
A34: Note 1: Only those members recruited or renewed during the period of 1 April - 31 March should be reported. The column "Total
A35: number of new and renewed members b/f from past period" should therefore be blank in April, the first month of the
A36: financial year. The indicator would only be evaluated at the end of the financial year when the total figure is available.

Sheet P2
A1: Output Standard 2 : Total number of core programme sessions (Note 2)
A2: [Agreed Level: 280 x (establishment of social workers* of the team as at 1.4.2000) within one year] (Note 3)
B4: Number of Core Program Sessions
A5: Month | B5: ( a ) | C5: ( b ) | D5: ( c ) | E5: Total/Average
A6: Types of programs | B6: ='P1'!B25 -> 0 | C6: ='P1'!C25 -> 0 | D6: ='P1'!D25 -> 0
A7: Guidance and counseling (group and activity) | E7: (i) | F7: =B7+C7+D7 -> 0
A8: (i) = (a) + (b) + (c)
A9: Guidance and counseling (case interview) (Note 4) | E9: (ii) | F9: =B9+C9+D9 -> 0
A10: (ii) = (a) + (b) + (c)
A11: Supportive service for young people in | E11: (iii) | F11: =B11+C11+D11 -> 0
A12: Disadvantaged circumstances (iii) = (a) + (b) + (c)
A13: Socialization programs | E13: (iv) | F13: =B13+C13+D13 -> 0
A14: (iv) = (a) + (b) + (c)
A15: Development of social responsibility and | E15: (v) | F15: =B15+C15+D15 -> 0
A16: Competence (v) = (a) + (b) + (c)
A17: Total (Output Standard 2) | B17: =B7+B9+B11+B13+B15 -> 0 | C17: =C7+C9+C11+C13+C15 -> 0 | D17: =D7+D9+D11+D13+D15 -> 0 | E17: (vi) | F17: =SUM(F7:F16) -> 0
A18: (i.e. (vi) = (i) + (ii) + (iii) + (iv) + (v)
A20: Output Standard 3 : Total core programme attendance
A21: [Agreed Level: 2,800 x (establishment of social workers* of the team as at 1.4.2000) within one year] (Note 3)
B23: Attendance
A24: Month | B24: ( a ) | C24: ( b ) | D24: ( c ) | E24: Total/Average
A25: Types of programs | B25: ='P1'!B25 -> 0 | C25: ='P1'!C25 -> 0 | D25: ='P1'!D25 -> 0
A26: Guidance and counseling (group and activity) | E26: (i) | F26: =B26+C26+D26 -> 0
A27: (i) = (a) + (b) + (c)
A28: Guidance and counseling (case interview) | E28: (ii) | F28: =B28+C28+D28 -> 0
A29: (ii) = (a) + (b) + (c)
A30: Supportive service for young people in | E30: (iii) | F30: =B30+C30+D30 -> 0
A31: Disadvantaged circumstances (iii) = (a) + (b) + ( c )
A32: Socialization programs | E32: (iv) | F32: =B32+C32+D32 -> 0
A33: (iv) = (a) + (b) + ( c )
A34: Development of social responsibility and | E34: (v) | F34: =B34+C34+D34 -> 0
A35: Competence (v) = (a) + (b) + (c)
A36: Total (Output Standard 2) | B36: =SUM(B26:B35) -> 0 | C36: =SUM(C26:C35) -> 0 | D36: =SUM(D26:D35) -> 0 | E36: (vi) | F36: =SUM(F26:F35) -> 0
A37: (vi = i + ii + iii + iv + v)
D38: .
A39: * Social Workers referred to social workers at the rank of SWA, SSWA and ASWO.
A41: Note 2: Core program should be made up of groups, activities and interviews.
A43: Note 3: 1.4.2000 is the date for the snapshot of establishment of social worker of the unit/agency when the agency declares
A44: options of the lump sum grant. This establishment would be the basis to calculate the Output Standards. However,
A45: when there is formation, expansion or reduction of the service during the year or after 1.4.2000, the
...

Sheet P3
A1: Output Standard 4 : Rate (%) of achieving core program plans (Note 5)
A2: (Agreed Level: 85% within one year)
A4: Format | B4: Groups ( a ) | C4: Activities ( b ) | D4: Cases ( c ) | E4: Total/Average
A5: Core programmes/ Cases
A6: Total no. of core programs completed/case closed in the quarter (i) = (a) + (b) + (c) | E6: (i) | F6: =SUM(B6:D6) -> 0
A7: Total no. of core programs completed/case closed with | E7: (ii) | F7: =SUM(B7:D9) -> 0
A8: goals achieved in the quarter
A9: (ii) = (a) + (b) + (c)
A10: Rate of (%) of achieving core program plans | E10: (iii) | F10: =F7*100/F6 -> #DIV/0!
A11: (Output Standard 4) (iii) = (ii) x 100%)
A12: (i)
A14: Output Standard 5 : Total number of service recipients at any one time (Note 6)
A15: [Agreed Level: 45 x (establishment of social workers* of the team as at 1.4.2000) within one year] (Note 3)
A17: Service recipients/Workers | B17: Quarter
B19: ='P1'!B25&"-"&'P1'!D25 -> -
A20: Total number of service recipients served by the unit in
A21: the quarter (Note 7)
A24: Note 5: (a) The following core programmes/cases (including joint programs/shared cases) should be reported:
A25: (i) Activities/ groups completed/terminated during the reporting period;
A26: (ii) Cases closed during the reporting period (cases only refer to those with treatment plans and case records).
A27: (iii) Ongoing activities/groups/cases which have been run/handled for 3 months or more as at 31 March should also
A28: be reported in the quarter of 1 January – 31 March.
A30: (b) For the purpose of this reporting, core programs completed/cases closed and ongoing core programs/cases which
A31: have been run/handled for 3 months or more as at 31 March must either be classified as “with goals achieved” or
A32: “with goals not achieved”
A34: Note 6: For the purpose of this reporting, “at any one time” is calculated on quarterly basis.
A36: Note 7: Total number of service recipients served by the unit refers to the sum of the number of service recipients served by
... A42: purposeful telephone interviews, escorts and home visits).

Sheet P4
A1: B. Average Opening sessions per week in the quarter (Note 8)
A3: Month | B3: ( a ) | C3: ( b ) | D3: ( c ) | E3: Total/Average
A4: Opening Sessions | B4: ='P1'!B25 -> 0 | C4: ='P1'!C25 -> 0 | D4: ='P1'!D25 -> 0
A5: Total number of opening sessions of the month | E5: (i) | F5: =SUM(B5:D5) -> 0
A6: (i) = (a) + (b) + (c)
A7: Total number of opening days of the month | E7: (ii) | F7: =SUM(B7:D7) -> 0
A8: (ii) = (a) + (b) + (c)
A9: Regular opening days per week (Note 9) | E9: (iii)
A10: (iii) = (a + b + c)
A11: 3
A12: Average adjusted number of opening sessions per week | E12: (iv) | F12: =F5/F7*F9 -> #DIV/0!
A13: [i.e. (i) x (iii)]
A14: (ii)
A16: C. SUPPLEMENTARY INFORMATION
A18: i. Caseload
A19: Movement of Cases | E19: No. of Cases
A20: (i) No. of Cases Brought Forward from Last Quarter
A21: (ii) No. of New Cases for the Quarter
A22: (iii) No. of Cases Closed for the Quarter
A23: (iv) Total No. of Cases to be Brought Forward to Next Quarter [i.e. (i) + (ii) – (iii)] | E23: ** | F23: =E20+E21-E22 -> 0
A26: ii. Nature of main problem of cases (one case one main problem)
D28: No. of Cases
A29: Month | C29: ='P1'!B25 -> 0 | D29: ='P1'!C25 -> 0 | E29: ='P1'!D25 -> 0
A30: Type
A31: 1. Health Problem
A32: 2. Schooling / Education Problem
A33: 3. Vocation
A34: 4. Peer Relationship Problem
A35: 5. Developmental Adjustment Problem
A36: 6. Emotional Problem
A37: 7. Sex-related Problem
A38: 8. Behavioural Problem
A39: 9. Family Problem
A40: 10. Others
A41: Total | C41: =#REF! -> #REF! | D41: =#REF! -> #REF! | E41: =#REF! -> #REF!
A42: ** The figures of these 2 columns should tally.
A43: Note 8: Opening sessions refer to sessions that are open to public.
A44: Note 9: The normal opening days of the centre per week irrespective of public holidays/block leave, e.g. 6 normal
A45: opening days per week. If the number of opening days per week in a particular month is varied, please take
A46: the average number.

Sheet P5
A1: iii. Potential Case Statistics
A2: No. of potential cases brought forward from last quarter (i) | C2: No. of new potential cases for the quarter (ii) | E2: No. of potential case | H2: No. pf potential case | K2: Total number of potential cases to be brought forward to the next quarter
E3: transferred (iii) | H3: terminated (iv)
C4: Brand New | D4: Re-opened | K4: (v) = (i) + (ii) – (iii) – (iv)
C5: =#REF! -> #REF! | E5: 0 | H5: 0 | K5: =A5+C5-E5-H5 -> #REF!
A7: C. Supplementary Information: Youth Development Programmes Organized (Note 10)
A9: Month | C9: ='P1'!B25 -> 0 | F9: ='P1'!C25 -> 0 | I9: ='P1'!D25 -> 0 | L9: Total
A10: Nature | C10: Total no. of programs | D10: Total no. of program sessions | E10: Total no. of attendance | F10: Total no. of programs | G10: Total no. of program sessions | H10: Total no. of attendance | I10: Total no. of programs | J10: Total no. of program sessions | K10: Total no. of attendance | L10: Total no. of programs | M10: Total no. of program sessions | N10: Total no. of attendance
A11: Leadership training | L11: =C11+F11+I11 -> 0 | M11: =D11+G11+J11 -> 0 | N11: =E11+H11+K11 -> 0
A12: (Note 11)
A13: Volunteerism | L13: =C13+F13+I13 -> 0 | M13: =D13+G13+J13 -> 0 | N13: =E13+H13+K13 -> 0
A14: (Note 12)
A15: Community participation | L15: =C15+F15+I15 -> 0 | M15: =D15+G15+J15 -> 0 | N15: =E15+H15+K15 -> 0
A16: (Note 13)
A17: Study/exchange program | L17: =C17+F17+I17 -> 0 | M17: =D17+G17+J17 -> 0 | N17: =E17+H17+K17 -> 0
A18: (Note 14)
A20: Note 10: The programs reported in this column could be overlapped with the programs reported in other columns of this
A21: form. Each program should only be entered once in this table.
A23: Note 11: Leadership training programs refer to structured training programs with the objective to develop the leadership,
A24: interpersonal communication and problem-solving skills of the young people.
A26: Note 12: Volunteerism refers to programs which could provide opportunities to the young people to serve others in the
A27: community and in the process, enable young people to acquire leadership skills, learn how to work with
A28: others, understand the needs of others and to cope with success and failure.
A30: Note 13: Community participation programs refer to those programs which could foster civic-awareness among the
A31: young people or provide opportunities for them to participate in community’s affairs.
A33: Note 14: Study/exchange programs refer to those programs which could facilitate the youths to learn more about
A34: mainland China and develop a better understanding of Chinese culture and heritage. Other
... A36: nationals and to respect their culture should be excluded.

Sheet P6
A2: D STAFF STATISTICS
A4: Establishments/Strength as at end of period
A5: (Please provide full particulars when you are completing this form for the first quarter of the
A6: financial year, whenever there are staff changes. If staff statistics remain the same as
A7: the preceding quarter, please enter no change across the table.)
A10: Rank | B10: Post | C10: Establishment | D10: Strength | E10: Vacancy | F10: Remarks
C13: NO | D13: CHANGE
A19: E. ADDITIONAL INFORMATION (e.g. significant activities, major planned programmes, etc.
A20: (Note: Please use additional paper for this section if necessary.)
A23: Prepared by: | B23: Chung Sze Ling | E23: Prepared by : | F23: Tang Wai Man
A24: Post: | B24: Programme Staff | E24: Post: | F24: Executive Secretary
A25: Tel. No.: | B25: 2322-0993 | E25: Tel. No.: | F25: 2322-0993
A26: Date: | B26: 42297 | E26: Date: | F26: 42297
